<?xml version="1.0" encoding="UTF-8"?>
<testng-results skipped="0" failed="2" ignored="0" total="3" passed="1">
  <reporter-output>
  </reporter-output>
  <suite name="Default suite" duration-ms="42918" started-at="2018-01-30T10:18:51Z" finished-at="2018-01-30T10:19:34Z">
    <groups>
    </groups>
    <test name="Default test" duration-ms="42918" started-at="2018-01-30T10:18:51Z" finished-at="2018-01-30T10:19:34Z">
      <class name="withoutExcel.testDDT">
        <test-method status="PASS" signature="setup()[pri:0, instance:withoutExcel.testDDT@74650e52]" name="setup" is-config="true" duration-ms="13576" started-at="2018-01-30T15:48:51Z" finished-at="2018-01-30T15:49:04Z">
          <reporter-output>
          </reporter-output>
        </test-method> <!-- setup -->
        <test-method status="FAIL" signature="loginselfservice(java.lang.String, java.lang.String)[pri:0, instance:withoutExcel.testDDT@74650e52]" name="loginselfservice" duration-ms="7494" started-at="2018-01-30T15:49:04Z" data-provider="logindata" finished-at="2018-01-30T15:49:12Z">
          <params>
            <param index="0">
              <value>
                <![CDATA[admin1]]>
              </value>
            </param>
            <param index="1">
              <value>
                <![CDATA[password1]]>
              </value>
            </param>
          </params>
          <exception class="java.lang.AssertionError">
            <message>
              <![CDATA[User login is successful expected [true] but found [false]]]>
            </message>
            <full-stacktrace>
              <![CDATA[java.lang.AssertionError: User login is successful expected [true] but found [false]at org.testng.Assert.fail(Assert.java:96)at org.testng.Assert.failNotEquals(Assert.java:776)at org.testng.Assert.assertTrue(Assert.java:44)at withoutExcel.testDDT.loginselfservice(testDDT.java:32)at sun.reflect.NativeMethodAccessorImpl.invoke0(Native Method)at sun.reflect.NativeMethodAccessorImpl.invoke(NativeMethodAccessorImpl.java:62)at sun.reflect.DelegatingMethodAccessorImpl.invoke(DelegatingMethodAccessorImpl.java:43)at java.lang.reflect.Method.invoke(Method.java:498)at org.testng.internal.MethodInvocationHelper.invokeMethod(MethodInvocationHelper.java:124)at org.testng.internal.Invoker.invokeMethod(Invoker.java:571)at org.testng.internal.Invoker.invokeTestMethod(Invoker.java:707)at org.testng.internal.Invoker.invokeTestMethods(Invoker.java:979)at org.testng.internal.TestMethodWorker.invokeTestMethods(TestMethodWorker.java:125)at org.testng.internal.TestMethodWorker.run(TestMethodWorker.java:109)at org.testng.TestRunner.privateRun(TestRunner.java:648)at org.testng.TestRunner.run(TestRunner.java:505)at org.testng.SuiteRunner.runTest(SuiteRunner.java:455)at org.testng.SuiteRunner.runSequentially(SuiteRunner.java:450)at org.testng.SuiteRunner.privateRun(SuiteRunner.java:415)at org.testng.SuiteRunner.run(SuiteRunner.java:364)at org.testng.SuiteRunnerWorker.runSuite(SuiteRunnerWorker.java:52)at org.testng.SuiteRunnerWorker.run(SuiteRunnerWorker.java:84)at org.testng.TestNG.runSuitesSequentially(TestNG.java:1187)at org.testng.TestNG.runSuitesLocally(TestNG.java:1116)at org.testng.TestNG.runSuites(TestNG.java:1028)at org.testng.TestNG.run(TestNG.java:996)at org.testng.remote.AbstractRemoteTestNG.run(AbstractRemoteTestNG.java:114)at org.testng.remote.RemoteTestNG.initAndRun(RemoteTestNG.java:251)at org.testng.remote.RemoteTestNG.main(RemoteTestNG.java:77)]]>
            </full-stacktrace>
          </exception> <!-- java.lang.AssertionError -->
          <reporter-output>
          </reporter-output>
        </test-method> <!-- loginselfservice -->
        <test-method status="FAIL" signature="loginselfservice(java.lang.String, java.lang.String)[pri:0, instance:withoutExcel.testDDT@74650e52]" name="loginselfservice" duration-ms="7348" started-at="2018-01-30T15:49:12Z" data-provider="logindata" finished-at="2018-01-30T15:49:19Z">
          <params>
            <param index="0">
              <value>
                <![CDATA[admin2]]>
              </value>
            </param>
            <param index="1">
              <value>
                <![CDATA[password2]]>
              </value>
            </param>
          </params>
          <exception class="java.lang.AssertionError">
            <message>
              <![CDATA[User login is successful expected [true] but found [false]]]>
            </message>
            <full-stacktrace>
              <![CDATA[java.lang.AssertionError: User login is successful expected [true] but found [false]at org.testng.Assert.fail(Assert.java:96)at org.testng.Assert.failNotEquals(Assert.java:776)at org.testng.Assert.assertTrue(Assert.java:44)at withoutExcel.testDDT.loginselfservice(testDDT.java:32)at sun.reflect.NativeMethodAccessorImpl.invoke0(Native Method)at sun.reflect.NativeMethodAccessorImpl.invoke(NativeMethodAccessorImpl.java:62)at sun.reflect.DelegatingMethodAccessorImpl.invoke(DelegatingMethodAccessorImpl.java:43)at java.lang.reflect.Method.invoke(Method.java:498)at org.testng.internal.MethodInvocationHelper.invokeMethod(MethodInvocationHelper.java:124)at org.testng.internal.Invoker.invokeMethod(Invoker.java:571)at org.testng.internal.Invoker.invokeTestMethod(Invoker.java:707)at org.testng.internal.Invoker.invokeTestMethods(Invoker.java:979)at org.testng.internal.TestMethodWorker.invokeTestMethods(TestMethodWorker.java:125)at org.testng.internal.TestMethodWorker.run(TestMethodWorker.java:109)at org.testng.TestRunner.privateRun(TestRunner.java:648)at org.testng.TestRunner.run(TestRunner.java:505)at org.testng.SuiteRunner.runTest(SuiteRunner.java:455)at org.testng.SuiteRunner.runSequentially(SuiteRunner.java:450)at org.testng.SuiteRunner.privateRun(SuiteRunner.java:415)at org.testng.SuiteRunner.run(SuiteRunner.java:364)at org.testng.SuiteRunnerWorker.runSuite(SuiteRunnerWorker.java:52)at org.testng.SuiteRunnerWorker.run(SuiteRunnerWorker.java:84)at org.testng.TestNG.runSuitesSequentially(TestNG.java:1187)at org.testng.TestNG.runSuitesLocally(TestNG.java:1116)at org.testng.TestNG.runSuites(TestNG.java:1028)at org.testng.TestNG.run(TestNG.java:996)at org.testng.remote.AbstractRemoteTestNG.run(AbstractRemoteTestNG.java:114)at org.testng.remote.RemoteTestNG.initAndRun(RemoteTestNG.java:251)at org.testng.remote.RemoteTestNG.main(RemoteTestNG.java:77)]]>
            </full-stacktrace>
          </exception> <!-- java.lang.AssertionError -->
          <reporter-output>
          </reporter-output>
        </test-method> <!-- loginselfservice -->
        <test-method status="PASS" signature="loginselfservice(java.lang.String, java.lang.String)[pri:0, instance:withoutExcel.testDDT@74650e52]" name="loginselfservice" duration-ms="12372" started-at="2018-01-30T15:49:19Z" data-provider="logindata" finished-at="2018-01-30T15:49:31Z">
          <params>
            <param index="0">
              <value>
                <![CDATA[Admin]]>
              </value>
            </param>
            <param index="1">
              <value>
                <![CDATA[E69@hz8yu]]>
              </value>
            </param>
          </params>
          <reporter-output>
          </reporter-output>
        </test-method> <!-- loginselfservice -->
        <test-method status="PASS" signature="teardown()[pri:0, instance:withoutExcel.testDDT@74650e52]" name="teardown" is-config="true" duration-ms="2099" started-at="2018-01-30T15:49:31Z" finished-at="2018-01-30T15:49:34Z">
          <reporter-output>
          </reporter-output>
        </test-method> <!-- teardown -->
      </class> <!-- withoutExcel.testDDT -->
    </test> <!-- Default test -->
  </suite> <!-- Default suite -->
</testng-results>
